Workbook
Name Amt: '[1]Name Ranges'!$D$10:$D$29
Name Cat: '[1]Name Ranges'!$C$10:$C$29
Name item_list: '[1]Name Ranges'!$B$9:$D$29
Name List1: OFFSET('[1]Dynamic Name range'!$D$27,0,0,COUNTA('[1]Dynamic Name range'!$D$27:$D$101),1)
Name List2: '[1]Dynamic Name range'!$D$28:INDEX('[1]Dynamic Name range'!$D$28:$D$101,COUNTA('[1]Dynamic Name range'!$D:$D))
Name No._of_Trades: #REF!:INDEX(#REF!,COUNTA(#REF!))
Name No.ofsharestraded: '[2]MATCH & INDEX'!$H$5:$H$23
Name No.ofsharestraded: '[3]MATCH & INDEX'!$H$5:$H$23
Name Salesquarter1: #REF!
Name Sharesheet: OFFSET([4]OFFSET!$A$22,,,COUNTA([4]OFFSET!$A:$A),COUNTA([4]OFFSET!$22:$22))
Name Traded_Contract__Lots: OFFSET('[1]Dynamic Name range'!$C$56,0,0,COUNTA('[1]Dynamic Name range'!$C$56:$C$100),1)
Name X: OFFSET([1]OFFSET!$D$23,0,0,COUNTA([1]OFFSET!$D$23:$D$99),1)

Sheet Sales Report
A1: Row ID | B1: Order ID | C1: Order Date | D1: Ship Date | E1: Ship Mode | F1: Customer Name | G1: Segment | H1: Country | I1: City | J1: State | K1: Postal Code | L1: Product ID | M1: Category | N1: Sub-Category | O1: Sales | P1: Quantity | Q1: Discount | R1: Profit | S1: Customer ID | T1: year | AF1: HA Q10
A2: 6100 | B2: CA-2017-100111 | C2: 42998 | D2: 43004 | E2: Standard Class | F2: Seth Vernon | G2: Consumer | H2: United States | I2: New York City | J2: New York | K2: 10035 | L2: FUR-CH-10004086 | M2: Furniture | N2: Chairs | O2: 2888.127 | P2: 11 | Q2: 0.1 | R2: 609.7157 | S2: SV-20365 | T2: =YEAR(C2:C25) -> 2017 | AF2: =IF(J2="Florida",IF(M2="Technology",IF(O2>300,"A","B"),""),"")
A3: 6117 | B3: US-2016-113677 | C3: 42687 | D3: 42693 | E3: Standard Class | F3: Corinna Mitchell | G3: Home Office | H3: United States | I3: New York City | J3: New York | K3: 10011 | L3: TEC-PH-10002114 | M3: Technology | N3: Phones | O3: 2279.96 | P3: 4 | Q3: 0 | R3: 592.7896 | S3: CM-12655 | T3: =YEAR(C3:C26) -> 2016 | AF3: =IF(J3="Florida",IF(M3="Technology",IF(O3>300,"A","B"),""),"")
A4: 6176 | B4: CA-2015-158421 | C4: 42268 | D4: 42273 | E4: Standard Class | F4: Giulietta Baptist | G4: Consumer | H4: United States | I4: Columbia | J4: South Carolina | K4: 29203 | L4: FUR-CH-10000309 | M4: Furniture | N4: Chairs | O4: 1690.04 | P4: 4 | Q4: 0 | R4: 422.51 | S4: GB-14575 | T4: =YEAR(C4:C27) -> 2015 | AF4: =IF(J4="Florida",IF(M4="Technology",IF(O4>300,"A","B"),""),"")
A5: 6102 | B5: CA-2017-100111 | C5: 42998 | D5: 43004 | E5: Standard Class | F5: Seth Vernon | G5: Consumer | H5: United States | I5: New York City | J5: New York | K5: 10035 | L5: FUR-CH-10001215 | M5: Furniture | N5: Chairs | O5: 2254.41 | P5: 5 | Q5: 0.1 | R5: 375.735 | S5: SV-20365 | T5: =YEAR(C5:C28) -> 2017 | AF5: =IF(J5="Florida",IF(M5="Technology",IF(O5>300,"A","B"),""),"")
A6: 6015 | B6: CA-2016-159016 | C6: 42439 | D6: 42440 | E6: First Class | F6: Karen Ferguson | G6: Home Office | H6: United States | I6: Los Angeles | J6: California | K6: 90008 | L6: TEC-PH-10002885 | M6: Technology | N6: Phones | O6: 4158.912 | P6: 8 | Q6: 0.2 | R6: 363.9048 | S6: KF-16285 | T6: =YEAR(C6:C29) -> 2016 | AF6: =IF(J6="Florida",IF(M6="Technology",IF(O6>300,"A","B"),""),"")
A7: 6101 | B7: CA-2017-100111 | C7: 42998 | D7: 43004 | E7: Standard Class | F7: Seth Vernon | G7: Consumer | H7: United States | I7: New York City | J7: New York | K7: 10035 | L7: TEC-PH-10002885 | M7: Technology | N7: Phones | O7: 1299.66 | P7: 2 | Q7: 0 | R7: 350.9082 | S7: SV-20365 | T7: =YEAR(C7:C30) -> 2017 | AF7: =IF(J7="Florida",IF(M7="Technology",IF(O7>300,"A","B"),""),"")
A8: 6011 | B8: CA-2015-135580 | C8: 42368 | D8: 42372 | E8: Standard Class | F8: Clay Ludtke | G8: Consumer | H8: United States | I8: Los Angeles | J8: California | K8: 90049 | L8: TEC-MA-10004002 | M8: Technology | N8: Machines | O8: 2548.56 | P8: 6 | Q8: 0.2 | R8: 286.713 | S8: CL-12565 | T8: =YEAR(C8:C31) -> 2015 | AF8: =IF(J8="Florida",IF(M8="Technology",IF(O8>300,"A","B"),""),"")
A9: 6175 | B9: US-2014-106299 | C9: 41853 | D9: 41859 | E9: Standard Class | F9: Nick Zandusky | G9: Home Office | H9: United States | I9: Springfield | J9: Missouri | K9: 65807 | L9: OFF-ST-10002011 | M9: Office Supplies | N9: Storage | O9: 838.38 | P9: 2 | Q9: 0 | R9: 226.3626 | S9: NZ-18565 | T9: =YEAR(C9:C32) -> 2014 | AF9: =IF(J9="Florida",IF(M9="Technology",IF(O9>300,"A","B"),""),"")
A10: 6063 | B10: CA-2015-111780 | C10: 42363 | D10: 42368 | E10: Second Class | F10: Ralph Arnett | G10: Consumer | H10: United States | I10: San Diego | J10: California | K10: 92037 | L10: TEC-CO-10004202 | M10: Technology | N10: Copiers | O10: 1199.96 | P10: 5 | Q10: 0.2 | R10: 224.9925 | S10: RA-19285 | T10: =YEAR(C10:C33) -> 2015 | AF10: =IF(J10="Florida",IF(M10="Technology",IF(O10>300,"A","B"),""),"")
A11: 6191 | B11: CA-2016-157259 | C11: 42728 | D11: 42732 | E11: Standard Class | F11: Jessica Myrick | G11: Consumer | H11: United States | I11: New York City | J11: New York | K11: 10035 | L11: FUR-FU-10003192 | M11: Furniture | N11: Furnishings | O11: 799.56 | P11: 9 | Q11: 0 | R11: 207.8856 | S11: JM-15535 | T11: =YEAR(C11:C34) -> 2016 | AF11: =IF(J11="Florida",IF(M11="Technology",IF(O11>300,"A","B"),""),"")
A12: 6077 | B12: CA-2016-151561 | C12: 42614 | D12: 42620 | E12: Standard Class | F12: Patrick Gardner | G12: Consumer | H12: United States | I12: New York City | J12: New York | K12: 10011 | L12: TEC-AC-10001432 | M12: Technology | N12: Accessories | O12: 468.9 | P12: 6 | Q12: 0 | R12: 206.316 | S12: PG-18820 | T12: =YEAR(C12:C35) -> 2016 | AF12: =IF(J12="Florida",IF(M12="Technology",IF(O12>300,"A","B"),""),"")
A13: 6042 | B13: CA-2017-122364 | C13: 43002 | D13: 43007 | E13: Standard Class | F13: Frank Atkinson | G13: Corporate | H13: United States | I13: Los Angeles | J13: California | K13: 90008 | L13: TEC-MA-10001031 | M13: Technology | N13: Machines | O13: 506.28 | P13: 3 | Q13: 0.2 | R13: 177.198 | S13: FA-14230 | T13: =YEAR(C13:C36) -> 2017 | AF13: =IF(J13="Florida",IF(M13="Technology",IF(O13>300,"A","B"),""),"")
... A25: 6143 | B25: CA-2017-121083 | C25: 42925 | D25: 42931 | E25: Standard Class | F25: Jamie Frazer | G25: Consumer | H25: United States | I25: Manchester | J25: Connecticut | K25: 6040 | L25: TEC-PH-10001336 | M25: Technology | N25: Phones | O25: 257.98 | P25: 2 | Q25: 0 | R25: 74.8142 | S25: JF-15190 | T25: =YEAR(C25:C48) -> 2017 | AF25: =IF(J25="Florida",IF(M25="Technology",IF(O25>300,"A","B"),""),"")

Sheet Data Validation
A1: Data Validation
A3: Data Validation in excel enables the user to restrict the kind of data that can be entered in to a certain cell or the range of cells.
A5: Data Validation allow users to restrict the input to:
A6: Only numeric or text values
A7: Only Numbers within a specified range
A8: Date and time within a specified time frame
A9: Specified entries from the drop down list
A11: Data Validation can also-
A12: Show an input message when the user selects the cell
A13: Show a warning message when the incorrect data has been entered
A14: Find incorrect entries in validated cell
A16: How to do Data Validation in Excel?
... A45: Example
A46: Row ID | B46: Order ID | C46: Order Date | D46: Ship Date | E46: Ship Mode | F46: Customer Name | G46: Segment
A47: 6200 | B47: CA-2016-159016 | C47: 42439 | D47: 42440 | E47: First Class | F47: Karen Ferguson | G47: home office
A48: 6117 | B48: CA-2017-100111 | C48: 42998 | D48: 43004 | E48: Standard Class | F48: Seth Vernon | G48: consumer
A49: 6176 | B49: CA-2015-135580 | C49: 42368 | D49: 42372 | E49: Standard Class | F49: Clay Ludtke | G49: corporate
A50: 6102 | B50: US-2016-113677 | C50: 42687 | D50: 42693 | E50: Standard Class | F50: Corinna Mitchell | G50: consumer
A51: 6015 | B51: CA-2017-100111 | C51: 42998 | D51: 43004 | E51: Standard Class | F51: Seth Vernon | G51: corporate
A52: 6101 | B52: CA-2015-158421 | C52: 42268 | D52: 42273 | E52: Standard Class | F52: Giulietta Baptist | G52: home office
A53: 6011 | B53: CA-2016-124590 | C53: 42686 | D53: 42690 | E53: Standard Class | F53: Susan Pistek | G53: corporate

Sheet Sum
A1: SUM
A3: It returns the sum of values given as arguments.
A4: Sum is the most popoular and commonly used function in Excel.
A6: Syntax
A7: SUM (number1, [number2], [number3], ...)
A9: number 1= first item to sum
A10: number 2 = second item to sum and so on
A12: Important
A13: The SUM function sums values supplied as arguments (up to 255 arguments).
A14: Arguments can be supplied as numbers, cell references, ranges, named ranges, constants, and the results of other formulas or functions.
A15: For example, SUM(C1:C3) adds all the numbers that are contained in cells C1 through C3, which is equivalent to SUM (C1, C2, C3)
A18: Example
A20: Product ID | B20: Category | C20: Sub-Category | D20: Product Name | E20: Sales | F20: Profit
A21: FUR-BO-10001798 | B21: Furniture | C21: Bookcases | D21: Bush Somerset Collection Bookcase | E21: 261.96 | F21: 609.72
A22: FUR-CH-10000454 | B22: Furniture | C22: Chairs | D22: Hon Deluxe Fabric Upholstered Stacking Chairs, Rounded Back | E22: 731.94 | F22: 592.79
A23: OFF-LA-10000240 | B23: Office Supplies | C23: Labels | D23: Self-Adhesive Address Labels for Typewriters by Universal | E23: 14.62 | F23: 422.51
A24: FUR-TA-10000577 | B24: Furniture | C24: Tables | D24: Bretford CR4500 Series Slim Rectangular Table | E24: 957.5775 | F24: 375.735
A25: OFF-ST-10000760 | B25: Office Supplies | C25: Storage | D25: Eldon Fold 'N Roll Cart System | E25: 22.368 | F25: 363.9048
E26: =SUM(E21:E25) -> 1988.4655 | F26: =SUM(F21:F25) -> 2364.6598
A28: SUMIF
A30: The SUMIF function adds all numbers in a range of cells based on one criteria. The criteria can be applied to date,numbers and text.
A34: Syntax
A36: SUMIF (range, criteria, [sum_range])
A38: range - The range of cells that you want to apply the criteria against
A39: criteria - The critieria used to determine which cells to add.
A40: sum_range - [optional] The cells to add together . If sum_range is omitted , the cells in range are added together instead.
A42: Important
A43: When sum_range is omitted, the cells in range will be summed.
A44: Text criteria, or criteria that includes math symbols, must be enclosed in double quotation marks (").
A45: Numeric criteria can be supplied without quotation marks.
A47: Example
A49: Order ID | B49: Order Date | C49: Product ID | D49: Category | E49: Sub-Category | F49: Sales
A50: CA-2016-152156 | B50: 42682 | C50: FUR-BO-10001798 | D50: Furniture | E50: Bookcases | F50: 261.96
A51: CA-2016-152156 | B51: 42682 | C51: FUR-CH-10000454 | D51: Furniture | E51: Chairs | F51: 731.94
A52: CA-2016-138688 | B52: 42533 | C52: OFF-LA-10000240 | D52: Office Supplies | E52: Labels | F52: 14.62
A53: US-2015-108966 | B53: 42288 | C53: FUR-TA-10000577 | D53: Furniture | E53: Tables | F53: 957.5775
A54: US-2015-108966 | B54: 42288 | C54: OFF-ST-10000760 | D54: Office Supplies | E54: Storage | F54: 22.368
A55: CA-2014-115812 | B55: 41799 | C55: FUR-FU-10001487 | D55: Furniture | E55: Furnishings | F55: 48.86
A56: CA-2014-115812 | B56: 41799 | C56: OFF-AR-10002833 | D56: Office Supplies | E56: Art | F56: 7.28
A57: CA-2014-115812 | B57: 41799 | C57: TEC-PH-10002275 | D57: Technology | E57: Phones | F57: 907.152
...

Sheet Count
A1: COUNT
A3: COUNT function counts the number of cells that contain numbers as well as the number of arguments that contain numbers.
A5: Syntax
A6: COUNT (argument 1, [argument 2], …argument_n)
A8: argument 1 - An item , cell reference, or range
A9: argument 2 - An item , cell reference, or range
A12: Important
A13: COUNT can handle up to 255 additional values.
A14: The logical values TRUE and FALSE are not counted.
A15: Empty cells and text are not counted.
A18: Example
A19: Order ID | B19: Order Date | C19: Customer | D19: Product ID | E19: Category | F19: Sub-Category | G19: Sales
A20: CA-2016-152156 | B20: 42682 | C20: Zuschuss Carroll | D20: FUR-BO-10001798 | E20: Furniture | F20: Bookcases | G20: 261.96
A21: CA-2016-152156 | B21: 42682 | C21: Jim Radford | D21: FUR-CH-10000454 | E21: Furniture | F21: Chairs | G21: 731.94
A22: CA-2016-138688 | B22: 42533 | C22: Cyma Kinney | D22: OFF-LA-10000240 | E22: Office Supplies | F22: Labels | G22: 14.62
A23: US-2015-108966 | B23: 42288 | C23: Stefania Perrino | D23: FUR-TA-10000577 | E23: Furniture | F23: Tables | G23: 957.5775
A24: US-2015-108966 | B24: 42288 | C24: Joel Eaton | D24: OFF-ST-10000760 | E24: Office Supplies | F24: Storage | G24: 22.368
A25: CA-2014-115812 | B25: 41799 | C25: Rick Hansen | D25: FUR-FU-10001487 | E25: Furniture | F25: Furnishings | G25: 48.86
A26: CA-2014-115812 | B26: 41799 | C26: Karen Daniels | D26: OFF-AR-10002833 | E26: Office Supplies | F26: Art | G26: 7.28
A27: CA-2014-115812 | B27: 41799 | C27: Adrian Barton | D27: TEC-PH-10002275 | E27: Technology | F27: Phones | G27: 907.152
A28: CA-2014-115812 | B28: 41799 | C28: Noel Staavos | D28: OFF-BI-10003910 | E28: Office Supplies | F28: Binders | G28: 18.504
A31: Calculate the number of orders placed
A32: =COUNT(G20:G28) -> 9
A34: Calculate the number of customers
A35: =COUNTA(C20:C28) -> 9
A37: COUNTIF
A39: COUNTIF is a function to count cells that meet a single criteria. It can be applied to date,number and text.
A43: Syntax
A44: COUNTIF(range, criteria)
A46: range- defines one or several cells to count
A47: criteria- defines the condition.the function counts the cell where the condition is true.
A50: Important
A51: Text criteria, or criteria that includes math symbols, must be enclosed in double quotation marks (").
A53: Example
A54: Order ID | B54: Order Date | C54: Category | D54: Sub-Category | E54: Sales | F54: CITY
A55: CA-2016-152156 | B55: 42682 | C55: Furniture | D55: Bookcases | E55: 261.96 | F55: Henderson
A56: CA-2016-152156 | B56: 42682 | C56: Furniture | D56: Chairs | E56: 731.94 | F56: Henderson
A57: CA-2016-138688 | B57: 42533 | C57: Office Supplies | D57: Labels | E57: 14.62 | F57: Los Angeles
A58: US-2015-108966 | B58: 42288 | C58: Furniture | D58: Tables | E58: 957.5775 | F58: Fort Lauderdale
A59: US-2015-108966 | B59: 42288 | C59: Office Supplies | D59: Storage | E59: 22.368 | F59: Fort Lauderdale
...

Sheet Average
A1: AVERAGE
A3: AVERAGE function returns the average (arithmetic mean) of the numbers provided
A4: Its purpose is to get the average of a group of numbers and it returns a number presenting the average
A7: Syntax
A8: AVERAGE (number1, [number2], ...)
A10: number1 - A number or cell reference that refers to numeric values.
A11: number2 - [optional] A number or cell reference that refers to numeric values.
A14: Important
A15: To calculate the average, Excel adds the numbers together and divides by the total number of numbers. For example, AVERAGE (2,4,6) returns 4.
A16: Numbers can be supplied as numbers, ranges, named ranges, or cell references that contain numeric values. Up to 255 numbers can be supplied.
A17: This function automatically ignores empty cells.
A19: Example
A20: Order ID | B20: Order Date | C20: Product ID | D20: Category | E20: Sub-Category | F20: Sales
A21: CA-2016-152156 | B21: 42682 | C21: FUR-BO-10001798 | D21: Furniture | E21: Bookcases | F21: 261.96
A22: CA-2016-152156 | B22: 42682 | C22: FUR-CH-10000454 | D22: Furniture | E22: Chairs | F22: 731.94
A23: CA-2016-138688 | B23: 42533 | C23: OFF-LA-10000240 | D23: Office Supplies | E23: Labels | F23: 14.62
A24: US-2015-108966 | B24: 42288 | C24: FUR-TA-10000577 | D24: Furniture | E24: Tables | F24: 957.578
A25: US-2015-108966 | B25: 42288 | C25: OFF-ST-10000760 | D25: Office Supplies | E25: Storage | F25: 22.368
A26: CA-2014-115812 | B26: 41799 | C26: FUR-FU-10001487 | D26: Furniture | E26: Furnishings | F26: 48.86
A27: CA-2014-115812 | B27: 41799 | C27: OFF-AR-10002833 | D27: Office Supplies | E27: Art | F27: 7.28
A28: CA-2014-115812 | B28: 41799 | C28: TEC-PH-10002275 | D28: Technology | E28: Phones | F28: 907.152
A29: CA-2014-115812 | B29: 41799 | C29: OFF-BI-10003910 | D29: Office Supplies | E29: Binders | F29: 18.504
A32: Calculate the Average sales done by the company
A33: =AVERAGE(F21:F29) -> 330.02911
A35: AVERAGEIF
A37: AVERAGEIF function returns the average of all numbers in a range of cells, based on a given criteria.
A38: Its purpose is to get the average of a group of numbers that meet the criteria and it returns a number presenting the average
A41: Syntax
A42: AVERAGEIF (range, criteria, [average_range])
A44: range - One or more cells, including numbers or names, arrays, or references.
A45: criteria - A number, expression, cell reference, or text.
A46: average_range - [optional] The cells to average. When omitted, range is used.
A49: Important
A50: Cells in range that contain TRUE or FALSE are ignored.
A51: Empty cells are ignored in range and average_range when calculating averages.
A52: AVERAGEIF returns #DIV/0! if no cells in range meet criteria.
... A56: EXAMPLE
A57: Order ID | B57: Order Date | C57: Product ID | D57: Category | E57: Sub-Category | F57: City | G57: Sales
A58: CA-2016-152156 | B58: 42682 | C58: FUR-BO-10001798 | D58: Furniture | E58: Bookcases | F58: Henderson | G58: 261.96
A59: CA-2016-152156 | B59: 42682 | C59: FUR-CH-10000454 | D59: Furniture | E59: Chairs | F59: Henderson | G59: 731.94
...

Sheet Practice Question 
A2: Q1 Provide the total sales of chairs sold to consumer segment
A3: =SUMIFS('Sales Report'!O2:O25,'Sales Report'!N2:N25,'Sales Report'!N2,'Sales Report'!G2:G25,'Sales Report'!G2) -> 6832.577
A5: Q2 Provide the average sales of Phones sold to Home Office Segment.
A6: =AVERAGEIFS('Sales Report'!O2:O25,'Sales Report'!N2:N25,'Sales Report'!N25,'Sales Report'!G2:G25,'Sales Report'!G16) -> 3219.436
A8: Q3.Count how many orders were placed through Standard mode
A9: =COUNTIF('Sales Report'!E2:E25,'Sales Report'!E2) -> 21
A11: Q4. Find out average sales of Furniture in home segment in Newyork City
A12: =AVERAGEIFS('Sales Report'!O2:O25,'Sales Report'!M2:M25,'Sales Report'!M22,'Sales Report'!G2:G25,'Sales Report'!G9,'Sales Report'!I2:I25,'Sales Report'!I12) -> 767.214
A14: Q5. Find out the number of machines sold to Corporate segment.
A15: =COUNTIFS('Sales Report'!N2:N25,'Sales Report'!N13,'Sales Report'!G2:G25,'Sales Report'!G13) -> 1
A17: Q6.Count the number of orders placed in :
A18: 2015 | B18: =COUNTIF('Sales Report'!T2:T25,'Sales Report'!T4) -> 7
A19: 2016 | B19: =COUNTIF('Sales Report'!T2:T25,'Sales Report'!T3) -> 7
A20: 2017 | B20: =COUNTIF('Sales Report'!T4:T27,'Sales Report'!T6) -> 6
A22: Q7. Provide the total sales of technology to the conumer segment in California
A23: =COUNTIFS('Sales Report'!M2:M25,'Sales Report'!M3,'Sales Report'!G2:G25,'Sales Report'!G7,'Sales Report'!J2:J25,'Sales Report'!J6) -> 2
A25: Q8. Find the total sales of office supplies to consumer segment in Los Angeles
A26: =SUMIFS('Sales Report'!O2:O25,'Sales Report'!M2:M25,'Sales Report'!M17,'Sales Report'!G2:G25,'Sales Report'!G2,'Sales Report'!I2:I25,'Sales Report'!I6) -> 1044.12
A28: Q9. Find the avaerage sales of technology to:
A29: Consumer | B29: =AVERAGEIFS('Sales Report'!O2:O25,'Sales Report'!M2:M25,'Sales Report'!M3,'Sales Report'!G2:G25,'Sales Report'!G2) -> 945.40143
A30: Home Office | B30: =AVERAGEIFS('Sales Report'!O2:O25,'Sales Report'!M2:M25,'Sales Report'!M3,'Sales Report'!G2:G25,'Sales Report'!G3) -> 3219.436
A31: Corporate | B31: =AVERAGEIFS('Sales Report'!O2:O25,'Sales Report'!M2:M25,'Sales Report'!M3,'Sales Report'!G2:G25,'Sales Report'!G21) -> 682.74
A33: Q10 Find the total sales of Furniture to the Consumer segment
A34: =SUMIFS('Sales Report'!O2:O25,'Sales Report'!M2:M25,'Sales Report'!M2,'Sales Report'!G2:G25,'Sales Report'!G2) -> 7987.037
